Workbook

Sheet SUMMARY
B2: Summary Fitness Tracking 2023
B5: Monthly Totals | G5: Daily Average | J5: 2023 Total
C7: ='Daily Recording'!D5 -> Steps | D7: ='Daily Recording'!E5 -> Mins | E7: ='Daily Recording'!F5 -> Reps
B8: JAN | C8: =SUM('Daily Recording'!D6:D36) -> 17060 | D8: =SUM('Daily Recording'!E6:E36) -> 200 | E8: =SUM('Daily Recording'!F6:F36) -> 230 | G8: =C7 -> Steps | H8: =AVERAGE('Daily Recording'!D6:D370) -> 5686.6667 | J8: =C7 -> Steps | K8: =SUM('Daily Recording'!D6:D370) -> 17060
B9: FEB | C9: =SUM('Daily Recording'!D37:D64) -> 0 | D9: =SUM('Daily Recording'!E37:E64) -> 0 | E9: =SUM('Daily Recording'!F37:F64) -> 0
B10: MAR | C10: =SUM('Daily Recording'!D65:D95) -> 0 | D10: =SUM('Daily Recording'!E65:E95) -> 0 | E10: =SUM('Daily Recording'!F65:F95) -> 0
B11: APR | C11: =SUM('Daily Recording'!D96:D125) -> 0 | D11: =SUM('Daily Recording'!E96:E125) -> 0 | E11: =SUM('Daily Recording'!F96:F125) -> 0
B12: MAY | C12: =SUM('Daily Recording'!D126:D156) -> 0 | D12: =SUM('Daily Recording'!E126:E156) -> 0 | E12: =SUM('Daily Recording'!F126:F156) -> 0 | G12: =D7 -> Mins | H12: =AVERAGE('Daily Recording'!E6:E370) -> 66.666667 | J12: =D7 -> Mins | K12: =SUM('Daily Recording'!E6:E370) -> 200
B13: JUN | C13: =SUM('Daily Recording'!D157:D186) -> 0 | D13: =SUM('Daily Recording'!E157:E186) -> 0 | E13: =SUM('Daily Recording'!F157:F186) -> 0
B14: JUL | C14: =SUM('Daily Recording'!D187:D217) -> 0 | D14: =SUM('Daily Recording'!E187:E217) -> 0 | E14: =SUM('Daily Recording'!F187:F217) -> 0
B15: AUG | C15: =SUM('Daily Recording'!D218:D248) -> 0 | D15: =SUM('Daily Recording'!E218:E248) -> 0 | E15: =SUM('Daily Recording'!F218:F248) -> 0
B16: SEP | C16: =SUM('Daily Recording'!D249:D278) -> 0 | D16: =SUM('Daily Recording'!E249:E278) -> 0 | E16: =SUM('Daily Recording'!F249:F278) -> 0 | G16: =E7 -> Reps | H16: =AVERAGE('Daily Recording'!F6:F370) -> 76.666667 | J16: =E7 -> Reps | K16: =SUM('Daily Recording'!F6:F370) -> 230
B17: OCT | C17: =SUM('Daily Recording'!D279:D309) -> 0 | D17: =SUM('Daily Recording'!E279:E309) -> 0 | E17: =SUM('Daily Recording'!F279:F309) -> 0
B18: NOV | C18: =SUM('Daily Recording'!D310:D339) -> 0 | D18: =SUM('Daily Recording'!E310:E339) -> 0 | E18: =SUM('Daily Recording'!F310:F339) -> 0
B19: DEC | C19: =SUM('Daily Recording'!D340:D370) -> 0 | D19: =SUM('Daily Recording'!E340:E370) -> 0 | E19: =SUM('Daily Recording'!F340:F370) -> 0

Sheet Daily Recording
B2: Daily Tracking / Counts | I2: Daily Target? | N2: Stuff for Summary Charts
C5: Date | D5: Steps | E5: Mins | F5: Reps | I5: =D5 -> Steps | J5: =E5 -> Mins | K5: =F5 -> Reps | N5: Week
B6: JANUARY | C6: 44927 | D6: 5000 | E6: 20 | F6: 60 | I6: 10000 | J6: 30 | K6: 50 | N6: =C6 -> 44927 | O6: =SUM(D6:D12) -> 17060
C7: 44928 | D7: 12000 | E7: 60 | F7: 100 | N7: =C13 -> 44934 | O7: =SUM(D13:D19) -> 0
C8: 44929 | D8: 60 | E8: 120 | F8: 70 | N8: =C20 -> 44941
C9: 44930 | N9: =C26 -> 44947
C10: 44931 | N10: =C33 -> 44954
C11: 44932 | N11: =C40 -> 44961
C12: 44933 | N12: =C47 -> 44968
C13: 44934 | N13: =C54 -> 44975
C14: 44935 | N14: =C61 -> 44982
C15: 44936 | N15: =C68 -> 44989
C16: 44937 | N16: =C75 -> 44996
C17: 44938 | N17: =C82 -> 45003
C18: 44939 | N18: =C89 -> 45010
C19: 44940 | N19: =C96 -> 45017
C20: 44941 | N20: =C103 -> 45024
C21: 44942 | N21: =C110 -> 45031
C22: 44943 | N22: =C117 -> 45038
C23: 44944 | N23: =C124 -> 45045
C24: 44945 | N24: =C131 -> 45052
C25: 44946 | N25: =C138 -> 45059
C26: 44947
C27: 44948
C28: 44949
C29: 44950
C30: 44951
C31: 44952
C32: 44953
C33: 44954
C34: 44955
C35: 44956
C36: 44957
B37: FEBRUARY | C37: 44958
C38: 44959
C39: 44960
C40: 44961
C41: 44962
C42: 44963
C43: 44964
...
